[2024-02-07T03:37:13.256+0000] {taskinstance.py:1956} INFO - Dependencies all met for dep_context=non-requeueable deps ti=<TaskInstance: Read_and_load_of_API_to_MySQLDB.Load_API_posts manual__2024-02-06T23:01:45.347640+00:00 [queued]>
[2024-02-07T03:37:13.275+0000] {taskinstance.py:1956} INFO - Dependencies all met for dep_context=requeueable deps ti=<TaskInstance: Read_and_load_of_API_to_MySQLDB.Load_API_posts manual__2024-02-06T23:01:45.347640+00:00 [queued]>
[2024-02-07T03:37:13.276+0000] {taskinstance.py:2170} INFO - Starting attempt 55 of 58
[2024-02-07T03:37:13.310+0000] {taskinstance.py:2191} INFO - Executing <Task(_PythonDecoratedOperator): Load_API_posts> on 2024-02-06 23:01:45.347640+00:00
[2024-02-07T03:37:13.325+0000] {standard_task_runner.py:60} INFO - Started process 176 to run task
[2024-02-07T03:37:13.330+0000] {standard_task_runner.py:87} INFO - Running: ['***', 'tasks', 'run', 'Read_and_load_of_API_to_MySQLDB', 'Load_API_posts', 'manual__2024-02-06T23:01:45.347640+00:00', '--job-id', '272', '--raw', '--subdir', 'DAGS_FOLDER/CRM.py', '--cfg-path', '/tmp/tmpxzi73txz']
[2024-02-07T03:37:13.334+0000] {standard_task_runner.py:88} INFO - Job 272: Subtask Load_API_posts
[2024-02-07T03:37:13.422+0000] {task_command.py:423} INFO - Running <TaskInstance: Read_and_load_of_API_to_MySQLDB.Load_API_posts manual__2024-02-06T23:01:45.347640+00:00 [running]> on host c35f28e50200
[2024-02-07T03:37:13.638+0000] {taskinstance.py:2480} INFO - Exporting env vars: AIRFLOW_CTX_DAG_OWNER='jmoc' AIRFLOW_CTX_DAG_ID='Read_and_load_of_API_to_MySQLDB' AIRFLOW_CTX_TASK_ID='Load_API_posts' AIRFLOW_CTX_EXECUTION_DATE='2024-02-06T23:01:45.347640+00:00' AIRFLOW_CTX_TRY_NUMBER='55' AIRFLOW_CTX_DAG_RUN_ID='manual__2024-02-06T23:01:45.347640+00:00'
[2024-02-07T03:37:14.380+0000] {base.py:83} INFO - Using connection ID 'redis_connection' for task execution.
[2024-02-07T03:37:14.426+0000] {taskinstance.py:2698} ERROR - Task failed with exception
Traceback (most recent call last):
  File "/home/airflow/.local/lib/python3.8/site-packages/airflow/models/taskinstance.py", line 433, in _execute_task
    result = execute_callable(context=context, **execute_callable_kwargs)
  File "/home/airflow/.local/lib/python3.8/site-packages/airflow/decorators/base.py", line 241, in execute
    return_value = super().execute(context)
  File "/home/airflow/.local/lib/python3.8/site-packages/airflow/operators/python.py", line 199, in execute
    return_value = self.execute_callable()
  File "/home/airflow/.local/lib/python3.8/site-packages/airflow/operators/python.py", line 216, in execute_callable
    return self.python_callable(*self.op_args, **self.op_kwargs)
  File "/opt/airflow/dags/CRM.py", line 102, in Load_API_posts
    hook.execute_command('SET', 'name', 'joe')
  File "/home/airflow/.local/lib/python3.8/site-packages/redis/client.py", line 1266, in execute_command
    conn = self.connection or pool.get_connection(command_name, **options)
  File "/home/airflow/.local/lib/python3.8/site-packages/redis/connection.py", line 1461, in get_connection
    connection.connect()
  File "/home/airflow/.local/lib/python3.8/site-packages/redis/connection.py", line 719, in connect
    self.on_connect()
  File "/home/airflow/.local/lib/python3.8/site-packages/redis/connection.py", line 763, in on_connect
    auth_response = self.read_response()
  File "/home/airflow/.local/lib/python3.8/site-packages/redis/connection.py", line 882, in read_response
    response = self._parser.read_response(disable_decoding=disable_decoding)
  File "/home/airflow/.local/lib/python3.8/site-packages/redis/connection.py", line 349, in read_response
    result = self._read_response(disable_decoding=disable_decoding)
  File "/home/airflow/.local/lib/python3.8/site-packages/redis/connection.py", line 372, in _read_response
    raise error
redis.exceptions.AuthenticationError: AUTH <password> called without any password configured for the default user. Are you sure your configuration is correct?
[2024-02-07T03:37:14.447+0000] {taskinstance.py:1138} INFO - Marking task as UP_FOR_RETRY. dag_id=Read_and_load_of_API_to_MySQLDB, task_id=Load_API_posts, execution_date=20240206T230145, start_date=20240207T033713, end_date=20240207T033714
[2024-02-07T03:37:14.480+0000] {standard_task_runner.py:107} ERROR - Failed to execute job 272 for task Load_API_posts (AUTH <password> called without any password configured for the default user. Are you sure your configuration is correct?; 176)
[2024-02-07T03:37:14.511+0000] {local_task_job_runner.py:234} INFO - Task exited with return code 1
[2024-02-07T03:37:14.546+0000] {taskinstance.py:3280} INFO - 0 downstream tasks scheduled from follow-on schedule check
