[2024-02-07T03:54:44.956+0000] {taskinstance.py:1956} INFO - Dependencies all met for dep_context=non-requeueable deps ti=<TaskInstance: Read_and_load_of_API_to_MySQLDB.Load_API_posts manual__2024-02-06T23:01:45.347640+00:00 [queued]>
[2024-02-07T03:54:44.977+0000] {taskinstance.py:1956} INFO - Dependencies all met for dep_context=requeueable deps ti=<TaskInstance: Read_and_load_of_API_to_MySQLDB.Load_API_posts manual__2024-02-06T23:01:45.347640+00:00 [queued]>
[2024-02-07T03:54:44.978+0000] {taskinstance.py:2170} INFO - Starting attempt 66 of 71
[2024-02-07T03:54:45.016+0000] {taskinstance.py:2191} INFO - Executing <Task(_PythonDecoratedOperator): Load_API_posts> on 2024-02-06 23:01:45.347640+00:00
[2024-02-07T03:54:45.023+0000] {standard_task_runner.py:60} INFO - Started process 584 to run task
[2024-02-07T03:54:45.027+0000] {standard_task_runner.py:87} INFO - Running: ['***', 'tasks', 'run', 'Read_and_load_of_API_to_MySQLDB', 'Load_API_posts', 'manual__2024-02-06T23:01:45.347640+00:00', '--job-id', '283', '--raw', '--subdir', 'DAGS_FOLDER/CRM.py', '--cfg-path', '/tmp/tmpuk9yxxb_']
[2024-02-07T03:54:45.032+0000] {standard_task_runner.py:88} INFO - Job 283: Subtask Load_API_posts
[2024-02-07T03:54:45.112+0000] {task_command.py:423} INFO - Running <TaskInstance: Read_and_load_of_API_to_MySQLDB.Load_API_posts manual__2024-02-06T23:01:45.347640+00:00 [running]> on host c35f28e50200
[2024-02-07T03:54:45.379+0000] {taskinstance.py:2480} INFO - Exporting env vars: AIRFLOW_CTX_DAG_OWNER='jmoc' AIRFLOW_CTX_DAG_ID='Read_and_load_of_API_to_MySQLDB' AIRFLOW_CTX_TASK_ID='Load_API_posts' AIRFLOW_CTX_EXECUTION_DATE='2024-02-06T23:01:45.347640+00:00' AIRFLOW_CTX_TRY_NUMBER='66' AIRFLOW_CTX_DAG_RUN_ID='manual__2024-02-06T23:01:45.347640+00:00'
[2024-02-07T03:54:45.833+0000] {base.py:83} INFO - Using connection ID 'redis_connection' for task execution.
[2024-02-07T03:54:45.855+0000] {taskinstance.py:2698} ERROR - Task failed with exception
Traceback (most recent call last):
  File "/home/airflow/.local/lib/python3.8/site-packages/airflow/models/taskinstance.py", line 433, in _execute_task
    result = execute_callable(context=context, **execute_callable_kwargs)
  File "/home/airflow/.local/lib/python3.8/site-packages/airflow/decorators/base.py", line 241, in execute
    return_value = super().execute(context)
  File "/home/airflow/.local/lib/python3.8/site-packages/airflow/operators/python.py", line 199, in execute
    return_value = self.execute_callable()
  File "/home/airflow/.local/lib/python3.8/site-packages/airflow/operators/python.py", line 216, in execute_callable
    return self.python_callable(*self.op_args, **self.op_kwargs)
  File "/opt/airflow/dags/CRM.py", line 102, in Load_API_posts
    hook.execute_command('SETEX', 'posts',json.dumps({'content':res}),604800)
  File "/home/airflow/.local/lib/python3.8/site-packages/redis/client.py", line 1269, in execute_command
    return conn.retry.call_with_retry(
  File "/home/airflow/.local/lib/python3.8/site-packages/redis/retry.py", line 46, in call_with_retry
    return do()
  File "/home/airflow/.local/lib/python3.8/site-packages/redis/client.py", line 1270, in <lambda>
    lambda: self._send_command_parse_response(
  File "/home/airflow/.local/lib/python3.8/site-packages/redis/client.py", line 1246, in _send_command_parse_response
    return self.parse_response(conn, command_name, **options)
  File "/home/airflow/.local/lib/python3.8/site-packages/redis/client.py", line 1286, in parse_response
    response = connection.read_response()
  File "/home/airflow/.local/lib/python3.8/site-packages/redis/connection.py", line 905, in read_response
    raise response
redis.exceptions.ResponseError: value is not an integer or out of range
[2024-02-07T03:54:45.876+0000] {taskinstance.py:1138} INFO - Marking task as UP_FOR_RETRY. dag_id=Read_and_load_of_API_to_MySQLDB, task_id=Load_API_posts, execution_date=20240206T230145, start_date=20240207T035444, end_date=20240207T035445
[2024-02-07T03:54:45.901+0000] {standard_task_runner.py:107} ERROR - Failed to execute job 283 for task Load_API_posts (value is not an integer or out of range; 584)
[2024-02-07T03:54:45.929+0000] {local_task_job_runner.py:234} INFO - Task exited with return code 1
[2024-02-07T03:54:45.971+0000] {taskinstance.py:3280} INFO - 0 downstream tasks scheduled from follow-on schedule check
