[2024-02-07T02:24:43.546+0000] {taskinstance.py:1956} INFO - Dependencies all met for dep_context=non-requeueable deps ti=<TaskInstance: Read_and_load_of_API_to_MySQLDB.Load_API_posts manual__2024-02-06T23:01:45.347640+00:00 [queued]>
[2024-02-07T02:24:43.564+0000] {taskinstance.py:1956} INFO - Dependencies all met for dep_context=requeueable deps ti=<TaskInstance: Read_and_load_of_API_to_MySQLDB.Load_API_posts manual__2024-02-06T23:01:45.347640+00:00 [queued]>
[2024-02-07T02:24:43.565+0000] {taskinstance.py:2170} INFO - Starting attempt 16 of 21
[2024-02-07T02:24:43.599+0000] {taskinstance.py:2191} INFO - Executing <Task(_PythonDecoratedOperator): Load_API_posts> on 2024-02-06 23:01:45.347640+00:00
[2024-02-07T02:24:43.610+0000] {standard_task_runner.py:60} INFO - Started process 707 to run task
[2024-02-07T02:24:43.616+0000] {standard_task_runner.py:87} INFO - Running: ['***', 'tasks', 'run', 'Read_and_load_of_API_to_MySQLDB', 'Load_API_posts', 'manual__2024-02-06T23:01:45.347640+00:00', '--job-id', '227', '--raw', '--subdir', 'DAGS_FOLDER/CRM.py', '--cfg-path', '/tmp/tmpvnzozov6']
[2024-02-07T02:24:43.622+0000] {standard_task_runner.py:88} INFO - Job 227: Subtask Load_API_posts
[2024-02-07T02:24:43.709+0000] {task_command.py:423} INFO - Running <TaskInstance: Read_and_load_of_API_to_MySQLDB.Load_API_posts manual__2024-02-06T23:01:45.347640+00:00 [running]> on host 1518ce13a9bd
[2024-02-07T02:24:43.881+0000] {taskinstance.py:2480} INFO - Exporting env vars: AIRFLOW_CTX_DAG_OWNER='jmoc' AIRFLOW_CTX_DAG_ID='Read_and_load_of_API_to_MySQLDB' AIRFLOW_CTX_TASK_ID='Load_API_posts' AIRFLOW_CTX_EXECUTION_DATE='2024-02-06T23:01:45.347640+00:00' AIRFLOW_CTX_TRY_NUMBER='16' AIRFLOW_CTX_DAG_RUN_ID='manual__2024-02-06T23:01:45.347640+00:00'
[2024-02-07T02:24:44.275+0000] {base.py:83} INFO - Using connection ID 'redis_connection' for task execution.
[2024-02-07T02:24:44.278+0000] {taskinstance.py:2698} ERROR - Task failed with exception
Traceback (most recent call last):
  File "/home/airflow/.local/lib/python3.8/site-packages/redis/connection.py", line 1454, in get_connection
    connection = self._available_connections.pop()
IndexError: pop from empty list

During handling of the above exception, another exception occurred:

Traceback (most recent call last):
  File "/home/airflow/.local/lib/python3.8/site-packages/airflow/models/taskinstance.py", line 433, in _execute_task
    result = execute_callable(context=context, **execute_callable_kwargs)
  File "/home/airflow/.local/lib/python3.8/site-packages/airflow/decorators/base.py", line 241, in execute
    return_value = super().execute(context)
  File "/home/airflow/.local/lib/python3.8/site-packages/airflow/operators/python.py", line 199, in execute
    return_value = self.execute_callable()
  File "/home/airflow/.local/lib/python3.8/site-packages/airflow/operators/python.py", line 216, in execute_callable
    return self.python_callable(*self.op_args, **self.op_kwargs)
  File "/opt/airflow/dags/CRM.py", line 99, in Load_API_posts
    hook.set('posts',res)
  File "/home/airflow/.local/lib/python3.8/site-packages/redis/commands/core.py", line 2328, in set
    return self.execute_command("SET", *pieces, **options)
  File "/home/airflow/.local/lib/python3.8/site-packages/redis/client.py", line 1266, in execute_command
    conn = self.connection or pool.get_connection(command_name, **options)
  File "/home/airflow/.local/lib/python3.8/site-packages/redis/connection.py", line 1456, in get_connection
    connection = self.make_connection()
  File "/home/airflow/.local/lib/python3.8/site-packages/redis/connection.py", line 1496, in make_connection
    return self.connection_class(**self.connection_kwargs)
  File "/home/airflow/.local/lib/python3.8/site-packages/redis/connection.py", line 956, in __init__
    self.port = int(port)
TypeError: int() argument must be a string, a bytes-like object or a number, not 'NoneType'
[2024-02-07T02:24:44.311+0000] {taskinstance.py:1138} INFO - Marking task as UP_FOR_RETRY. dag_id=Read_and_load_of_API_to_MySQLDB, task_id=Load_API_posts, execution_date=20240206T230145, start_date=20240207T022443, end_date=20240207T022444
[2024-02-07T02:24:44.338+0000] {standard_task_runner.py:107} ERROR - Failed to execute job 227 for task Load_API_posts (int() argument must be a string, a bytes-like object or a number, not 'NoneType'; 707)
[2024-02-07T02:24:44.395+0000] {local_task_job_runner.py:234} INFO - Task exited with return code 1
[2024-02-07T02:24:44.426+0000] {taskinstance.py:3280} INFO - 0 downstream tasks scheduled from follow-on schedule check
