[2024-02-07T02:26:09.308+0000] {taskinstance.py:1956} INFO - Dependencies all met for dep_context=non-requeueable deps ti=<TaskInstance: Read_and_load_of_API_to_MySQLDB.Load_API_posts manual__2024-02-06T23:01:45.347640+00:00 [queued]>
[2024-02-07T02:26:09.331+0000] {taskinstance.py:1956} INFO - Dependencies all met for dep_context=requeueable deps ti=<TaskInstance: Read_and_load_of_API_to_MySQLDB.Load_API_posts manual__2024-02-06T23:01:45.347640+00:00 [queued]>
[2024-02-07T02:26:09.332+0000] {taskinstance.py:2170} INFO - Starting attempt 18 of 23
[2024-02-07T02:26:09.375+0000] {taskinstance.py:2191} INFO - Executing <Task(_PythonDecoratedOperator): Load_API_posts> on 2024-02-06 23:01:45.347640+00:00
[2024-02-07T02:26:09.382+0000] {standard_task_runner.py:60} INFO - Started process 753 to run task
[2024-02-07T02:26:09.389+0000] {standard_task_runner.py:87} INFO - Running: ['***', 'tasks', 'run', 'Read_and_load_of_API_to_MySQLDB', 'Load_API_posts', 'manual__2024-02-06T23:01:45.347640+00:00', '--job-id', '229', '--raw', '--subdir', 'DAGS_FOLDER/CRM.py', '--cfg-path', '/tmp/tmpqmstnfso']
[2024-02-07T02:26:09.392+0000] {standard_task_runner.py:88} INFO - Job 229: Subtask Load_API_posts
[2024-02-07T02:26:09.491+0000] {task_command.py:423} INFO - Running <TaskInstance: Read_and_load_of_API_to_MySQLDB.Load_API_posts manual__2024-02-06T23:01:45.347640+00:00 [running]> on host 1518ce13a9bd
[2024-02-07T02:26:09.684+0000] {taskinstance.py:2480} INFO - Exporting env vars: AIRFLOW_CTX_DAG_OWNER='jmoc' AIRFLOW_CTX_DAG_ID='Read_and_load_of_API_to_MySQLDB' AIRFLOW_CTX_TASK_ID='Load_API_posts' AIRFLOW_CTX_EXECUTION_DATE='2024-02-06T23:01:45.347640+00:00' AIRFLOW_CTX_TRY_NUMBER='18' AIRFLOW_CTX_DAG_RUN_ID='manual__2024-02-06T23:01:45.347640+00:00'
[2024-02-07T02:26:10.076+0000] {base.py:83} INFO - Using connection ID 'redis_connection' for task execution.
[2024-02-07T02:26:10.078+0000] {taskinstance.py:2698} ERROR - Task failed with exception
Traceback (most recent call last):
  File "/home/airflow/.local/lib/python3.8/site-packages/airflow/models/taskinstance.py", line 433, in _execute_task
    result = execute_callable(context=context, **execute_callable_kwargs)
  File "/home/airflow/.local/lib/python3.8/site-packages/airflow/decorators/base.py", line 241, in execute
    return_value = super().execute(context)
  File "/home/airflow/.local/lib/python3.8/site-packages/airflow/operators/python.py", line 199, in execute
    return_value = self.execute_callable()
  File "/home/airflow/.local/lib/python3.8/site-packages/airflow/operators/python.py", line 216, in execute_callable
    return self.python_callable(*self.op_args, **self.op_kwargs)
  File "/opt/airflow/dags/CRM.py", line 99, in Load_API_posts
    print(dict(res))
ValueError: dictionary update sequence element #0 has length 4; 2 is required
[2024-02-07T02:26:10.114+0000] {taskinstance.py:1138} INFO - Marking task as UP_FOR_RETRY. dag_id=Read_and_load_of_API_to_MySQLDB, task_id=Load_API_posts, execution_date=20240206T230145, start_date=20240207T022609, end_date=20240207T022610
[2024-02-07T02:26:10.155+0000] {standard_task_runner.py:107} ERROR - Failed to execute job 229 for task Load_API_posts (dictionary update sequence element #0 has length 4; 2 is required; 753)
[2024-02-07T02:26:10.210+0000] {local_task_job_runner.py:234} INFO - Task exited with return code 1
[2024-02-07T02:26:10.241+0000] {taskinstance.py:3280} INFO - 0 downstream tasks scheduled from follow-on schedule check
