[2024-02-15T20:17:54.523+0000] {taskinstance.py:1956} INFO - Dependencies all met for dep_context=non-requeueable deps ti=<TaskInstance: Read_and_load_of_API_to_MySQLDB.cities_table scheduled__2024-02-04T00:00:00+00:00 [queued]>
[2024-02-15T20:17:54.550+0000] {taskinstance.py:1956} INFO - Dependencies all met for dep_context=requeueable deps ti=<TaskInstance: Read_and_load_of_API_to_MySQLDB.cities_table scheduled__2024-02-04T00:00:00+00:00 [queued]>
[2024-02-15T20:17:54.552+0000] {taskinstance.py:2170} INFO - Starting attempt 8 of 12
[2024-02-15T20:17:54.585+0000] {taskinstance.py:2191} INFO - Executing <Task(_PythonDecoratedOperator): cities_table> on 2024-02-04 00:00:00+00:00
[2024-02-15T20:17:54.596+0000] {standard_task_runner.py:60} INFO - Started process 420 to run task
[2024-02-15T20:17:54.605+0000] {standard_task_runner.py:87} INFO - Running: ['***', 'tasks', 'run', 'Read_and_load_of_API_to_MySQLDB', 'cities_table', 'scheduled__2024-02-04T00:00:00+00:00', '--job-id', '345', '--raw', '--subdir', 'DAGS_FOLDER/CRM.py', '--cfg-path', '/tmp/tmppsqdp_4t']
[2024-02-15T20:17:54.610+0000] {standard_task_runner.py:88} INFO - Job 345: Subtask cities_table
[2024-02-15T20:17:54.914+0000] {task_command.py:423} INFO - Running <TaskInstance: Read_and_load_of_API_to_MySQLDB.cities_table scheduled__2024-02-04T00:00:00+00:00 [running]> on host 9ed0078b97b9
[2024-02-15T20:17:55.134+0000] {taskinstance.py:2480} INFO - Exporting env vars: AIRFLOW_CTX_DAG_OWNER='jmoc' AIRFLOW_CTX_DAG_ID='Read_and_load_of_API_to_MySQLDB' AIRFLOW_CTX_TASK_ID='cities_table' AIRFLOW_CTX_EXECUTION_DATE='2024-02-04T00:00:00+00:00' AIRFLOW_CTX_TRY_NUMBER='8' AIRFLOW_CTX_DAG_RUN_ID='scheduled__2024-02-04T00:00:00+00:00'
[2024-02-15T20:17:55.140+0000] {taskinstance.py:2698} ERROR - Task failed with exception
Traceback (most recent call last):
  File "/home/airflow/.local/lib/python3.8/site-packages/airflow/models/taskinstance.py", line 433, in _execute_task
    result = execute_callable(context=context, **execute_callable_kwargs)
  File "/home/airflow/.local/lib/python3.8/site-packages/airflow/decorators/base.py", line 241, in execute
    return_value = super().execute(context)
  File "/home/airflow/.local/lib/python3.8/site-packages/airflow/operators/python.py", line 199, in execute
    return_value = self.execute_callable()
  File "/home/airflow/.local/lib/python3.8/site-packages/airflow/operators/python.py", line 216, in execute_callable
    return self.python_callable(*self.op_args, **self.op_kwargs)
  File "/opt/airflow/dags/CRM.py", line 41, in cities_table
    mysql_hook.run(airflow_PI.cities_c())
TypeError: cities_c() missing 1 required positional argument: 'self'
[2024-02-15T20:17:55.160+0000] {taskinstance.py:1138} INFO - Marking task as UP_FOR_RETRY. dag_id=Read_and_load_of_API_to_MySQLDB, task_id=cities_table, execution_date=20240204T000000, start_date=20240215T201754, end_date=20240215T201755
[2024-02-15T20:17:55.214+0000] {standard_task_runner.py:107} ERROR - Failed to execute job 345 for task cities_table (cities_c() missing 1 required positional argument: 'self'; 420)
[2024-02-15T20:17:55.248+0000] {local_task_job_runner.py:234} INFO - Task exited with return code 1
[2024-02-15T20:17:55.300+0000] {taskinstance.py:3280} INFO - 0 downstream tasks scheduled from follow-on schedule check
