[2024-02-18T01:51:59.040+0000] {taskinstance.py:1956} INFO - Dependencies all met for dep_context=non-requeueable deps ti=<TaskInstance: Read_and_load_of_API_to_MySQLDB.Load_users_registers scheduled__2024-02-11T00:00:00+00:00 [queued]>
[2024-02-18T01:51:59.061+0000] {taskinstance.py:1956} INFO - Dependencies all met for dep_context=requeueable deps ti=<TaskInstance: Read_and_load_of_API_to_MySQLDB.Load_users_registers scheduled__2024-02-11T00:00:00+00:00 [queued]>
[2024-02-18T01:51:59.064+0000] {taskinstance.py:2170} INFO - Starting attempt 6 of 9
[2024-02-18T01:51:59.095+0000] {taskinstance.py:2191} INFO - Executing <Task(_PythonDecoratedOperator): Load_users_registers> on 2024-02-11 00:00:00+00:00
[2024-02-18T01:51:59.105+0000] {standard_task_runner.py:60} INFO - Started process 1967 to run task
[2024-02-18T01:51:59.109+0000] {standard_task_runner.py:87} INFO - Running: ['***', 'tasks', 'run', 'Read_and_load_of_API_to_MySQLDB', 'Load_users_registers', 'scheduled__2024-02-11T00:00:00+00:00', '--job-id', '527', '--raw', '--subdir', 'DAGS_FOLDER/CRM.py', '--cfg-path', '/tmp/tmpoh2mzkrv']
[2024-02-18T01:51:59.115+0000] {standard_task_runner.py:88} INFO - Job 527: Subtask Load_users_registers
[2024-02-18T01:51:59.221+0000] {task_command.py:423} INFO - Running <TaskInstance: Read_and_load_of_API_to_MySQLDB.Load_users_registers scheduled__2024-02-11T00:00:00+00:00 [running]> on host 091c4b0f3ebe
[2024-02-18T01:51:59.417+0000] {taskinstance.py:2480} INFO - Exporting env vars: AIRFLOW_CTX_DAG_OWNER='jmoc' AIRFLOW_CTX_DAG_ID='Read_and_load_of_API_to_MySQLDB' AIRFLOW_CTX_TASK_ID='Load_users_registers' AIRFLOW_CTX_EXECUTION_DATE='2024-02-11T00:00:00+00:00' AIRFLOW_CTX_TRY_NUMBER='6' AIRFLOW_CTX_DAG_RUN_ID='scheduled__2024-02-11T00:00:00+00:00'
[2024-02-18T01:51:59.454+0000] {base.py:83} INFO - Using connection ID 'mysql_connection' for task execution.
[2024-02-18T01:51:59.606+0000] {sql.py:450} INFO - Running statement: SELECT id FROM cities WHERE name = 'Gwenborough';, parameters: None
[2024-02-18T01:51:59.644+0000] {sql.py:459} INFO - Rows affected: 1
[2024-02-18T01:51:59.665+0000] {base.py:83} INFO - Using connection ID 'mysql_connection' for task execution.
[2024-02-18T01:51:59.676+0000] {sql.py:450} INFO - Running statement: SELECT id FROM companies WHERE name = 'Romaguera-Crona';, parameters: None
[2024-02-18T01:51:59.696+0000] {sql.py:459} INFO - Rows affected: 1
[2024-02-18T01:51:59.723+0000] {base.py:83} INFO - Using connection ID 'mysql_connection' for task execution.
[2024-02-18T01:51:59.774+0000] {sql.py:450} INFO - Running statement: INSERT IGNORE INTO users(name, username, email, address, city_id, zipcode, latitud, longitud, phone, website, company_id) VALUES ('Leanne Graham','Bret','Sincere@april.biz','Kulas Light Apt. 556','7','92998-3874','-37.3159','81.1496','1-770-736-8031 x56442','hildegard.org','1');, parameters: None
[2024-02-18T01:51:59.857+0000] {sql.py:459} INFO - Rows affected: 0
[2024-02-18T01:51:59.922+0000] {base.py:83} INFO - Using connection ID 'postgres_connection' for task execution.
[2024-02-18T01:51:59.961+0000] {sql.py:450} INFO - Running statement: INSERT INTO users (name, username, email, address, city_id, zipcode, latitud, longitud, phone, website, company_id) VALUES ('Leanne Graham','Bret','Sincere@april.biz','Kulas Light Apt. 556','7','92998-3874','-37.3159','81.1496','1-770-736-8031 x56442','hildegard.org','1') ON CONFLICT (email) DO NOTHING;, parameters: None
[2024-02-18T01:51:59.978+0000] {taskinstance.py:2698} ERROR - Task failed with exception
Traceback (most recent call last):
  File "/home/airflow/.local/lib/python3.8/site-packages/airflow/models/taskinstance.py", line 433, in _execute_task
    result = execute_callable(context=context, **execute_callable_kwargs)
  File "/home/airflow/.local/lib/python3.8/site-packages/airflow/decorators/base.py", line 241, in execute
    return_value = super().execute(context)
  File "/home/airflow/.local/lib/python3.8/site-packages/airflow/operators/python.py", line 199, in execute
    return_value = self.execute_callable()
  File "/home/airflow/.local/lib/python3.8/site-packages/airflow/operators/python.py", line 216, in execute_callable
    return self.python_callable(*self.op_args, **self.op_kwargs)
  File "/opt/airflow/dags/CRM.py", line 99, in Load_users_registers
    user_register.save()
  File "/opt/airflow/dags/models/User.py", line 28, in save
    postgres_hook.run(postgres_statement)
  File "/home/airflow/.local/lib/python3.8/site-packages/airflow/providers/common/sql/hooks/sql.py", line 398, in run
    self._run_command(cur, sql_statement, parameters)
  File "/home/airflow/.local/lib/python3.8/site-packages/airflow/providers/common/sql/hooks/sql.py", line 455, in _run_command
    cur.execute(sql_statement)
psycopg2.errors.ForeignKeyViolation: insert or update on table "users" violates foreign key constraint "users_city_id_fkey"
DETAIL:  Key (city_id)=(7) is not present in table "cities".

[2024-02-18T01:52:00.072+0000] {taskinstance.py:1138} INFO - Marking task as UP_FOR_RETRY. dag_id=Read_and_load_of_API_to_MySQLDB, task_id=Load_users_registers, execution_date=20240211T000000, start_date=20240218T015159, end_date=20240218T015200
[2024-02-18T01:52:00.131+0000] {standard_task_runner.py:107} ERROR - Failed to execute job 527 for task Load_users_registers (insert or update on table "users" violates foreign key constraint "users_city_id_fkey"
DETAIL:  Key (city_id)=(7) is not present in table "cities".
; 1967)
[2024-02-18T01:52:00.177+0000] {local_task_job_runner.py:234} INFO - Task exited with return code 1
[2024-02-18T01:52:00.302+0000] {taskinstance.py:3280} INFO - 0 downstream tasks scheduled from follow-on schedule check
