[2024-02-18T01:40:01.063+0000] {taskinstance.py:1956} INFO - Dependencies all met for dep_context=non-requeueable deps ti=<TaskInstance: Read_and_load_of_API_to_MySQLDB.Load_users_registers scheduled__2024-02-11T00:00:00+00:00 [queued]>
[2024-02-18T01:40:01.084+0000] {taskinstance.py:1956} INFO - Dependencies all met for dep_context=requeueable deps ti=<TaskInstance: Read_and_load_of_API_to_MySQLDB.Load_users_registers scheduled__2024-02-11T00:00:00+00:00 [queued]>
[2024-02-18T01:40:01.086+0000] {taskinstance.py:2170} INFO - Starting attempt 2 of 6
[2024-02-18T01:40:01.112+0000] {taskinstance.py:2191} INFO - Executing <Task(_PythonDecoratedOperator): Load_users_registers> on 2024-02-11 00:00:00+00:00
[2024-02-18T01:40:01.121+0000] {standard_task_runner.py:60} INFO - Started process 1699 to run task
[2024-02-18T01:40:01.126+0000] {standard_task_runner.py:87} INFO - Running: ['***', 'tasks', 'run', 'Read_and_load_of_API_to_MySQLDB', 'Load_users_registers', 'scheduled__2024-02-11T00:00:00+00:00', '--job-id', '513', '--raw', '--subdir', 'DAGS_FOLDER/CRM.py', '--cfg-path', '/tmp/tmpuh5456hr']
[2024-02-18T01:40:01.129+0000] {standard_task_runner.py:88} INFO - Job 513: Subtask Load_users_registers
[2024-02-18T01:40:01.235+0000] {task_command.py:423} INFO - Running <TaskInstance: Read_and_load_of_API_to_MySQLDB.Load_users_registers scheduled__2024-02-11T00:00:00+00:00 [running]> on host 091c4b0f3ebe
[2024-02-18T01:40:01.503+0000] {taskinstance.py:2480} INFO - Exporting env vars: AIRFLOW_CTX_DAG_OWNER='jmoc' AIRFLOW_CTX_DAG_ID='Read_and_load_of_API_to_MySQLDB' AIRFLOW_CTX_TASK_ID='Load_users_registers' AIRFLOW_CTX_EXECUTION_DATE='2024-02-11T00:00:00+00:00' AIRFLOW_CTX_TRY_NUMBER='2' AIRFLOW_CTX_DAG_RUN_ID='scheduled__2024-02-11T00:00:00+00:00'
[2024-02-18T01:40:01.566+0000] {base.py:83} INFO - Using connection ID 'mysql_connection' for task execution.
[2024-02-18T01:40:01.618+0000] {sql.py:450} INFO - Running statement: SELECT id FROM cities WHERE name = 'Gwenborough';, parameters: None
[2024-02-18T01:40:01.627+0000] {sql.py:459} INFO - Rows affected: 1
[2024-02-18T01:40:01.640+0000] {base.py:83} INFO - Using connection ID 'mysql_connection' for task execution.
[2024-02-18T01:40:01.650+0000] {sql.py:450} INFO - Running statement: SELECT id FROM companies WHERE name = 'Romaguera-Crona';, parameters: None
[2024-02-18T01:40:01.652+0000] {sql.py:459} INFO - Rows affected: 1
[2024-02-18T01:40:01.663+0000] {base.py:83} INFO - Using connection ID 'mysql_connection' for task execution.
[2024-02-18T01:40:01.670+0000] {sql.py:450} INFO - Running statement: INSERT IGNORE INTO users(name, username, email, address, city_id, zipcode, latitud, longitud, phone, website, company_id) VALUES ('Leanne Graham','Bret','Sincere@april.biz','Kulas Light Apt. 556','7','92998-3874','-37.3159','81.1496','1-770-736-8031 x56442','hildegard.org','1');, parameters: None
[2024-02-18T01:40:01.679+0000] {sql.py:459} INFO - Rows affected: 0
[2024-02-18T01:40:01.694+0000] {base.py:83} INFO - Using connection ID 'postgres_connection' for task execution.
[2024-02-18T01:40:01.704+0000] {sql.py:450} INFO - Running statement: INSERT INTO users (name, username, email, address, city_id, zipcode, latitud, longitud, phone, website, company_id) VALUES ('Leanne Graham','Bret','Sincere@april.biz','Kulas Light Apt. 556','7','92998-3874','-37.3159','81.1496','1-770-736-8031 x56442','hildegard.org','1') ON CONFLICT (email) DO NOTHING;, parameters: None
[2024-02-18T01:40:01.709+0000] {taskinstance.py:2698} ERROR - Task failed with exception
Traceback (most recent call last):
  File "/home/airflow/.local/lib/python3.8/site-packages/airflow/models/taskinstance.py", line 433, in _execute_task
    result = execute_callable(context=context, **execute_callable_kwargs)
  File "/home/airflow/.local/lib/python3.8/site-packages/airflow/decorators/base.py", line 241, in execute
    return_value = super().execute(context)
  File "/home/airflow/.local/lib/python3.8/site-packages/airflow/operators/python.py", line 199, in execute
    return_value = self.execute_callable()
  File "/home/airflow/.local/lib/python3.8/site-packages/airflow/operators/python.py", line 216, in execute_callable
    return self.python_callable(*self.op_args, **self.op_kwargs)
  File "/opt/airflow/dags/CRM.py", line 99, in Load_users_registers
    user_register.save()
  File "/opt/airflow/dags/models/User.py", line 28, in save
    postgres_hook.run(postgres_statement)
  File "/home/airflow/.local/lib/python3.8/site-packages/airflow/providers/common/sql/hooks/sql.py", line 398, in run
    self._run_command(cur, sql_statement, parameters)
  File "/home/airflow/.local/lib/python3.8/site-packages/airflow/providers/common/sql/hooks/sql.py", line 455, in _run_command
    cur.execute(sql_statement)
psycopg2.errors.StringDataRightTruncation: value too long for type character varying(15)

[2024-02-18T01:40:01.738+0000] {taskinstance.py:1138} INFO - Marking task as UP_FOR_RETRY. dag_id=Read_and_load_of_API_to_MySQLDB, task_id=Load_users_registers, execution_date=20240211T000000, start_date=20240218T014001, end_date=20240218T014001
[2024-02-18T01:40:01.769+0000] {standard_task_runner.py:107} ERROR - Failed to execute job 513 for task Load_users_registers (value too long for type character varying(15)
; 1699)
[2024-02-18T01:40:01.785+0000] {local_task_job_runner.py:234} INFO - Task exited with return code 1
[2024-02-18T01:40:01.833+0000] {taskinstance.py:3280} INFO - 0 downstream tasks scheduled from follow-on schedule check
