[2024-02-18T00:46:03.123+0000] {taskinstance.py:1956} INFO - Dependencies all met for dep_context=non-requeueable deps ti=<TaskInstance: Read_and_load_of_API_to_MySQLDB.Load_companies_registers scheduled__2024-02-11T00:00:00+00:00 [queued]>
[2024-02-18T00:46:03.146+0000] {taskinstance.py:1956} INFO - Dependencies all met for dep_context=requeueable deps ti=<TaskInstance: Read_and_load_of_API_to_MySQLDB.Load_companies_registers scheduled__2024-02-11T00:00:00+00:00 [queued]>
[2024-02-18T00:46:03.147+0000] {taskinstance.py:2170} INFO - Starting attempt 4 of 6
[2024-02-18T00:46:03.187+0000] {taskinstance.py:2191} INFO - Executing <Task(_PythonDecoratedOperator): Load_companies_registers> on 2024-02-11 00:00:00+00:00
[2024-02-18T00:46:03.200+0000] {standard_task_runner.py:60} INFO - Started process 509 to run task
[2024-02-18T00:46:03.208+0000] {standard_task_runner.py:87} INFO - Running: ['***', 'tasks', 'run', 'Read_and_load_of_API_to_MySQLDB', 'Load_companies_registers', 'scheduled__2024-02-11T00:00:00+00:00', '--job-id', '502', '--raw', '--subdir', 'DAGS_FOLDER/CRM.py', '--cfg-path', '/tmp/tmpfedgjho3']
[2024-02-18T00:46:03.212+0000] {standard_task_runner.py:88} INFO - Job 502: Subtask Load_companies_registers
[2024-02-18T00:46:03.340+0000] {task_command.py:423} INFO - Running <TaskInstance: Read_and_load_of_API_to_MySQLDB.Load_companies_registers scheduled__2024-02-11T00:00:00+00:00 [running]> on host 091c4b0f3ebe
[2024-02-18T00:46:03.612+0000] {taskinstance.py:2480} INFO - Exporting env vars: AIRFLOW_CTX_DAG_OWNER='jmoc' AIRFLOW_CTX_DAG_ID='Read_and_load_of_API_to_MySQLDB' AIRFLOW_CTX_TASK_ID='Load_companies_registers' AIRFLOW_CTX_EXECUTION_DATE='2024-02-11T00:00:00+00:00' AIRFLOW_CTX_TRY_NUMBER='4' AIRFLOW_CTX_DAG_RUN_ID='scheduled__2024-02-11T00:00:00+00:00'
[2024-02-18T00:46:03.676+0000] {base.py:83} INFO - Using connection ID 'mysql_connection' for task execution.
[2024-02-18T00:46:03.710+0000] {sql.py:450} INFO - Running statement: INSERT IGNORE INTO ***.companies(name, catchPhrase, bs) VALUES ('Romaguera-Crona','Multi-layered client-server neural-net', 'harness real-time e-markets');, parameters: None
[2024-02-18T00:46:03.718+0000] {sql.py:459} INFO - Rows affected: 0
[2024-02-18T00:46:03.747+0000] {base.py:83} INFO - Using connection ID 'postgres_connection' for task execution.
[2024-02-18T00:46:03.756+0000] {sql.py:450} INFO - Running statement: INSERT INTO ***.companies(name, catchPhrase, bs) VALUES ('Romaguera-Crona','Multi-layered client-server neural-net', 'harness real-time e-markets') ON CONFLICT DO NOTHING;, parameters: None
[2024-02-18T00:46:03.759+0000] {taskinstance.py:2698} ERROR - Task failed with exception
Traceback (most recent call last):
  File "/home/airflow/.local/lib/python3.8/site-packages/airflow/models/taskinstance.py", line 433, in _execute_task
    result = execute_callable(context=context, **execute_callable_kwargs)
  File "/home/airflow/.local/lib/python3.8/site-packages/airflow/decorators/base.py", line 241, in execute
    return_value = super().execute(context)
  File "/home/airflow/.local/lib/python3.8/site-packages/airflow/operators/python.py", line 199, in execute
    return_value = self.execute_callable()
  File "/home/airflow/.local/lib/python3.8/site-packages/airflow/operators/python.py", line 216, in execute_callable
    return self.python_callable(*self.op_args, **self.op_kwargs)
  File "/opt/airflow/dags/CRM.py", line 83, in Load_companies_registers
    company_register.save()
  File "/opt/airflow/dags/models/Company.py", line 21, in save
    postgres_hook.run(postgres_statement)
  File "/home/airflow/.local/lib/python3.8/site-packages/airflow/providers/common/sql/hooks/sql.py", line 398, in run
    self._run_command(cur, sql_statement, parameters)
  File "/home/airflow/.local/lib/python3.8/site-packages/airflow/providers/common/sql/hooks/sql.py", line 455, in _run_command
    cur.execute(sql_statement)
psycopg2.errors.UndefinedTable: relation "***.companies" does not exist
LINE 1: INSERT INTO ***.companies(name, catchPhrase, bs) VALUES ...
                    ^

[2024-02-18T00:46:03.800+0000] {taskinstance.py:1138} INFO - Marking task as UP_FOR_RETRY. dag_id=Read_and_load_of_API_to_MySQLDB, task_id=Load_companies_registers, execution_date=20240211T000000, start_date=20240218T004603, end_date=20240218T004603
[2024-02-18T00:46:03.829+0000] {standard_task_runner.py:107} ERROR - Failed to execute job 502 for task Load_companies_registers (relation "***.companies" does not exist
LINE 1: INSERT INTO ***.companies(name, catchPhrase, bs) VALUES ...
                    ^
; 509)
[2024-02-18T00:46:03.855+0000] {local_task_job_runner.py:234} INFO - Task exited with return code 1
[2024-02-18T00:46:03.908+0000] {taskinstance.py:3280} INFO - 0 downstream tasks scheduled from follow-on schedule check
