[2024-02-06T19:08:55.891+0000] {taskinstance.py:1956} INFO - Dependencies all met for dep_context=non-requeueable deps ti=<TaskInstance: Read_and_load_of_API_to_MySQLDB.Load_users_registers manual__2024-02-06T03:05:04.018386+00:00 [queued]>
[2024-02-06T19:08:55.917+0000] {taskinstance.py:1956} INFO - Dependencies all met for dep_context=requeueable deps ti=<TaskInstance: Read_and_load_of_API_to_MySQLDB.Load_users_registers manual__2024-02-06T03:05:04.018386+00:00 [queued]>
[2024-02-06T19:08:55.919+0000] {taskinstance.py:2170} INFO - Starting attempt 7 of 12
[2024-02-06T19:08:55.955+0000] {taskinstance.py:2191} INFO - Executing <Task(_PythonDecoratedOperator): Load_users_registers> on 2024-02-06 03:05:04.018386+00:00
[2024-02-06T19:08:55.965+0000] {standard_task_runner.py:60} INFO - Started process 671 to run task
[2024-02-06T19:08:55.969+0000] {standard_task_runner.py:87} INFO - Running: ['***', 'tasks', 'run', 'Read_and_load_of_API_to_MySQLDB', 'Load_users_registers', 'manual__2024-02-06T03:05:04.018386+00:00', '--job-id', '169', '--raw', '--subdir', 'DAGS_FOLDER/CRM.py', '--cfg-path', '/tmp/tmpyiatna33']
[2024-02-06T19:08:55.972+0000] {standard_task_runner.py:88} INFO - Job 169: Subtask Load_users_registers
[2024-02-06T19:08:56.055+0000] {task_command.py:423} INFO - Running <TaskInstance: Read_and_load_of_API_to_MySQLDB.Load_users_registers manual__2024-02-06T03:05:04.018386+00:00 [running]> on host 648978c3a8b9
[2024-02-06T19:08:56.231+0000] {taskinstance.py:2480} INFO - Exporting env vars: AIRFLOW_CTX_DAG_OWNER='jmoc' AIRFLOW_CTX_DAG_ID='Read_and_load_of_API_to_MySQLDB' AIRFLOW_CTX_TASK_ID='Load_users_registers' AIRFLOW_CTX_EXECUTION_DATE='2024-02-06T03:05:04.018386+00:00' AIRFLOW_CTX_TRY_NUMBER='7' AIRFLOW_CTX_DAG_RUN_ID='manual__2024-02-06T03:05:04.018386+00:00'
[2024-02-06T19:08:56.271+0000] {base.py:83} INFO - Using connection ID 'mysql_connection' for task execution.
[2024-02-06T19:08:56.291+0000] {sql.py:450} INFO - Running statement: SELECT id FROM ***_PI.cities WHERE name = Gwenborough, parameters: None
[2024-02-06T19:08:56.463+0000] {taskinstance.py:2698} ERROR - Task failed with exception
Traceback (most recent call last):
  File "/home/airflow/.local/lib/python3.8/site-packages/airflow/models/taskinstance.py", line 433, in _execute_task
    result = execute_callable(context=context, **execute_callable_kwargs)
  File "/home/airflow/.local/lib/python3.8/site-packages/airflow/decorators/base.py", line 241, in execute
    return_value = super().execute(context)
  File "/home/airflow/.local/lib/python3.8/site-packages/airflow/operators/python.py", line 199, in execute
    return_value = self.execute_callable()
  File "/home/airflow/.local/lib/python3.8/site-packages/airflow/operators/python.py", line 216, in execute_callable
    return self.python_callable(*self.op_args, **self.op_kwargs)
  File "/opt/airflow/dags/CRM.py", line 84, in Load_users_registers
    res = City.findId(x['address']['city'])
  File "/opt/airflow/dags/models/City.py", line 19, in findId
    res = hook.run(mysql_statement)
  File "/home/airflow/.local/lib/python3.8/site-packages/airflow/providers/common/sql/hooks/sql.py", line 398, in run
    self._run_command(cur, sql_statement, parameters)
  File "/home/airflow/.local/lib/python3.8/site-packages/airflow/providers/common/sql/hooks/sql.py", line 455, in _run_command
    cur.execute(sql_statement)
  File "/home/airflow/.local/lib/python3.8/site-packages/MySQLdb/cursors.py", line 179, in execute
    res = self._query(mogrified_query)
  File "/home/airflow/.local/lib/python3.8/site-packages/MySQLdb/cursors.py", line 330, in _query
    db.query(q)
  File "/home/airflow/.local/lib/python3.8/site-packages/MySQLdb/connections.py", line 257, in query
    _mysql.connection.query(self, query)
MySQLdb.OperationalError: (1054, "Unknown column 'Gwenborough' in 'where clause'")
[2024-02-06T19:08:56.492+0000] {taskinstance.py:1138} INFO - Marking task as UP_FOR_RETRY. dag_id=Read_and_load_of_API_to_MySQLDB, task_id=Load_users_registers, execution_date=20240206T030504, start_date=20240206T190855, end_date=20240206T190856
[2024-02-06T19:08:56.518+0000] {standard_task_runner.py:107} ERROR - Failed to execute job 169 for task Load_users_registers ((1054, "Unknown column 'Gwenborough' in 'where clause'"); 671)
[2024-02-06T19:08:56.546+0000] {local_task_job_runner.py:234} INFO - Task exited with return code 1
[2024-02-06T19:08:56.582+0000] {taskinstance.py:3280} INFO - 0 downstream tasks scheduled from follow-on schedule check
