[2024-02-16T21:07:34.868+0000] {taskinstance.py:1956} INFO - Dependencies all met for dep_context=non-requeueable deps ti=<TaskInstance: Read_and_load_of_API_to_MySQLDB.companies_table scheduled__2024-02-04T00:00:00+00:00 [queued]>
[2024-02-16T21:07:34.936+0000] {taskinstance.py:1956} INFO - Dependencies all met for dep_context=requeueable deps ti=<TaskInstance: Read_and_load_of_API_to_MySQLDB.companies_table scheduled__2024-02-04T00:00:00+00:00 [queued]>
[2024-02-16T21:07:34.938+0000] {taskinstance.py:2170} INFO - Starting attempt 22 of 27
[2024-02-16T21:07:35.023+0000] {taskinstance.py:2191} INFO - Executing <Task(_PythonDecoratedOperator): companies_table> on 2024-02-04 00:00:00+00:00
[2024-02-16T21:07:35.043+0000] {standard_task_runner.py:60} INFO - Started process 872 to run task
[2024-02-16T21:07:35.059+0000] {standard_task_runner.py:87} INFO - Running: ['***', 'tasks', 'run', 'Read_and_load_of_API_to_MySQLDB', 'companies_table', 'scheduled__2024-02-04T00:00:00+00:00', '--job-id', '415', '--raw', '--subdir', 'DAGS_FOLDER/CRM.py', '--cfg-path', '/tmp/tmpfa6bwvzk']
[2024-02-16T21:07:35.070+0000] {standard_task_runner.py:88} INFO - Job 415: Subtask companies_table
[2024-02-16T21:07:35.284+0000] {task_command.py:423} INFO - Running <TaskInstance: Read_and_load_of_API_to_MySQLDB.companies_table scheduled__2024-02-04T00:00:00+00:00 [running]> on host 1db157a9f142
[2024-02-16T21:07:35.992+0000] {taskinstance.py:2480} INFO - Exporting env vars: AIRFLOW_CTX_DAG_OWNER='jmoc' AIRFLOW_CTX_DAG_ID='Read_and_load_of_API_to_MySQLDB' AIRFLOW_CTX_TASK_ID='companies_table' AIRFLOW_CTX_EXECUTION_DATE='2024-02-04T00:00:00+00:00' AIRFLOW_CTX_TRY_NUMBER='22' AIRFLOW_CTX_DAG_RUN_ID='scheduled__2024-02-04T00:00:00+00:00'
[2024-02-16T21:07:36.020+0000] {base.py:83} INFO - Using connection ID 'mysql_connection' for task execution.
[2024-02-16T21:07:36.047+0000] {sql.py:450} INFO - Running statement: 
            CREATE TABLE IF NOT EXISTS ***.companies(
              id INT AUTO_INCREMENT  PRIMARY KEY NOT NULL,
              name VARCHAR(25) NOT NULL UNIQUE  ,
              catchPhrase VARCHAR(225) NOT NULL,
              bs VARCHAR(50) NOT NULL 
            );
            , parameters: None
[2024-02-16T21:07:36.059+0000] {taskinstance.py:2698} ERROR - Task failed with exception
Traceback (most recent call last):
  File "/home/airflow/.local/lib/python3.8/site-packages/airflow/models/taskinstance.py", line 433, in _execute_task
    result = execute_callable(context=context, **execute_callable_kwargs)
  File "/home/airflow/.local/lib/python3.8/site-packages/airflow/decorators/base.py", line 241, in execute
    return_value = super().execute(context)
  File "/home/airflow/.local/lib/python3.8/site-packages/airflow/operators/python.py", line 199, in execute
    return_value = self.execute_callable()
  File "/home/airflow/.local/lib/python3.8/site-packages/airflow/operators/python.py", line 216, in execute_callable
    return self.python_callable(*self.op_args, **self.op_kwargs)
  File "/opt/airflow/dags/CRM.py", line 46, in companies_table
    mysql_hook.run(db.companies_c())
  File "/home/airflow/.local/lib/python3.8/site-packages/airflow/providers/common/sql/hooks/sql.py", line 398, in run
    self._run_command(cur, sql_statement, parameters)
  File "/home/airflow/.local/lib/python3.8/site-packages/airflow/providers/common/sql/hooks/sql.py", line 455, in _run_command
    cur.execute(sql_statement)
  File "/home/airflow/.local/lib/python3.8/site-packages/MySQLdb/cursors.py", line 179, in execute
    res = self._query(mogrified_query)
  File "/home/airflow/.local/lib/python3.8/site-packages/MySQLdb/cursors.py", line 330, in _query
    db.query(q)
  File "/home/airflow/.local/lib/python3.8/site-packages/MySQLdb/connections.py", line 257, in query
    _mysql.connection.query(self, query)
MySQLdb.OperationalError: (1049, "Unknown database '***'")
[2024-02-16T21:07:36.117+0000] {taskinstance.py:1138} INFO - Marking task as UP_FOR_RETRY. dag_id=Read_and_load_of_API_to_MySQLDB, task_id=companies_table, execution_date=20240204T000000, start_date=20240216T210734, end_date=20240216T210736
[2024-02-16T21:07:36.204+0000] {standard_task_runner.py:107} ERROR - Failed to execute job 415 for task companies_table ((1049, "Unknown database '***'"); 872)
[2024-02-16T21:07:36.268+0000] {local_task_job_runner.py:234} INFO - Task exited with return code 1
[2024-02-16T21:07:36.391+0000] {taskinstance.py:3280} INFO - 0 downstream tasks scheduled from follow-on schedule check
